terminate called after throwing an instance of 'std::out_of_range'
  what():  stoi
Aborted

return code: 134
